<?xml version="1.0"?>
<robot name="simple_bot">

  <!-- Base footprint -->
  <link name="base_footprint"/>
  <joint name="base_footprint_joint" type="fixed">
    <parent link="base_footprint"/>
    <child link="base_link"/>
    <origin xyz="0 0 0.06" rpy="0 0 0"/> 
  </joint>

  <!-- Base -->
  <link name="base_link">
    <visual>
      <geometry>
        <box size="0.3 0.3 0.1"/>
      </geometry>
      <origin xyz = "0 0 0" rpy = "0 0 0"/>
    </visual>
    <collision>
      <geometry>
        <box size="0.3 0.3 0.1"/>
      </geometry>
      <origin xyz = "0 0 0" rpy = "0 0 0"/>
    </collision>
    <inertial>
      <origin xyz = "0 0 0" rpy = "0 0 0"/>
      <mass value="1.0"/>
      <inertia
        ixx="0.1" 
        ixy="0.0"
        ixz="0.0"
        iyy="0.1"
        iyz="0.0"
        izz="0.1"/>
    </inertial>
  </link>

  <!-- Left wheel -->
  <link name="left_wheel_link">
    <visual>
      <geometry>
        <cylinder radius="0.05" length="0.02"/>
      </geometry>
      <origin rpy="1.5708 0 0"/>
    </visual>
    <collision>
      <geometry>
        <cylinder radius="0.05" length="0.02"/>
      </geometry>
      <origin rpy="1.5708 0 0"/>
    </collision>
    <inertial>
      <origin xyz="0 0 0" rpy="1.5708 0 0"/>
      <mass value="0.1"/>
      <inertia 
        ixx="0.001" 
        ixy="0.0" 
        ixz="0.0" 
        iyy="0.001" 
        iyz="0.0" 
        izz="0.001"/>
    </inertial>
  </link>

  <!-- Right wheel -->
  <link name="right_wheel_link">
    <visual>
      <geometry>
        <cylinder radius="0.05" length="0.02"/>
      </geometry>
      <origin rpy="1.5708 0 0"/>
    </visual>
    <collision>
      <geometry>
        <cylinder radius="0.05" length="0.02"/>
      </geometry>
      <origin rpy="1.5708 0 0"/>
    </collision>
    <inertial>
      <origin xyz="0 0 0" rpy="1.5708 0 0"/>
      <mass value="0.1"/>
      <inertia 
        ixx="0.001" 
        ixy="0.0" 
        ixz="0.0" 
        iyy="0.001" 
        iyz="0.0" 
        izz="0.001"/>
    </inertial>
  </link>

  <!-- Left wheel joint -->
  <joint name="left_wheel_joint" type="continuous">
    <parent link="base_link"/>
    <child link="left_wheel_link"/>
    <origin xyz="0 0.15 -0.01"/>
    <axis xyz="0 1 0"/>
  </joint>

  <!-- Right wheel joint -->
  <joint name="right_wheel_joint" type="continuous">
    <parent link="base_link"/>
    <child link="right_wheel_link"/>
    <origin xyz="0 -0.15 -0.01"/>
    <axis xyz="0 1 0"/>
  </joint>


  <!-- LiDAR -->
  <link name="lidar_link"/>

  <joint name="lidar_joint" type="fixed">
    <parent link="base_link"/>
    <child link="lidar_link"/>
    <origin xyz="0 0 0.15"/>
  </joint>

  <!-- Gazebo LiDAR sensor -->
  <gazebo reference="lidar_link">
    <sensor type="ray" name="lidar">
      <pose>0 0 0 0 0 0</pose>
      <update_rate>10</update_rate>

      <ray>
        <scan>
          <horizontal>
            <samples>360</samples>
            <resolution>1</resolution>
            <min_angle>-3.14159</min_angle>
            <max_angle>3.14159</max_angle>
          </horizontal>
        </scan>

        <range>
          <min>0.12</min>
          <max>3.5</max>
          <resolution>0.01</resolution>
        </range>
      </ray>

      <plugin name="laser_controller" filename="libgazebo_ros_ray_sensor.so">
        <ros>
          <remapping>~/out:=scan</remapping>
        </ros>
        <output_type>sensor_msgs/LaserScan</output_type>
        <frame_name>lidar_link</frame_name>
      </plugin>
    </sensor>
  </gazebo>

  <gazebo>
    <plugin name="diff_drive_controller" filename="libgazebo_ros_diff_drive.so">
      <ros>
        <remapping>cmd_vel:=cmd_vel</remapping>
      </ros>

      <left_joint>left_wheel_joint</left_joint>
      <right_joint>right_wheel_joint</right_joint>

      <wheel_separation>0.30</wheel_separation>
      <wheel_diameter>0.1</wheel_diameter>
      <publish_wheel_tf>true</publish_wheel_tf>

      <publish_odom>true</publish_odom>
      <publish_odom_tf>true</publish_odom_tf>
      <odom_frame>odom</odom_frame>
      <base_frame>base_link</base_frame>
    </plugin>
  </gazebo>

</robot>